<mujoco>
    <include file="materials.xml"/>
    <compiler angle="degree" coordinate="local" inertiafromgeom="true"/>
    <option iterations="50" timestep="0.005000" tolerance="0.000000" cone="pyramidal" jacobian="dense" solver="Newton"/>
    <size nconmax="4000" njmax="8000"/>
    <statistic extent="2.000000" center="0.000000 0.000000 1.000000"/>
    <asset>
        <texture height="512" width="512" rgb1="0.300000 0.500000 0.700000" rgb2="0.000000 0.000000 0.000000" builtin="gradient" type="skybox"/>
        <texture height="512" width="512" markrgb="0.800000 0.800000 0.800000" rgb1="0.200000 0.300000 0.400000" rgb2="0.100000 0.150000 0.200000" builtin="checker" mark="cross" name="texplane" type="2d"/>
        <texture height="1278" width="127" random="0.010000" markrgb="1.000000 1.000000 1.000000" rgb1="0.800000 0.600000 0.400000" rgb2="0.800000 0.600000 0.400000" builtin="flat" mark="cross" name="texgeom" type="cube"/>
        <material reflectance="0.300000" texrepeat="1.000000 1.000000" name="matplane" texture="texplane" texuniform="true"/>
        <material rgba="0.800000 0.600000 0.400000 1.000000" name="matgeom" texture="texgeom" texuniform="true"/>
    </asset>
    <visual>
        <map force="0.100000" zfar="30.000000"/>
        <rgba haze="0.150000 0.250000 0.350000 1.000000"/>
        <quality shadowsize="2048"/>
        <global offheight="800" offwidth="800"/>
    </visual>
    <worldbody>
        <body pos="0.000000 0.000000 1.000000" quat="1.000000 0.000000 0.000000 0.000000" name="body_agent0_torso">
            <joint name="joint_agent0_root" type="free"/>
            <geom conaffinity="0" condim="3" density="5.000000" friction="1.000000 0.500000 0.500000" pos="0.000000 0.000000 0.000000" quat="1.000000 0.000000 0.000000 0.000000" rgba="0.800000 0.600000 0.400000 1.000000" size="0.250000 0.000000 0.000000" name="geom_agent0_torso_geom" type="sphere"/>
            <body pos="0.000000 0.000000 0.000000" quat="1.000000 0.000000 0.000000 0.000000" name="body_agent0_front_left_leg">
                <geom conaffinity="0" condim="3" density="5.000000" friction="1.000000 0.500000 0.500000" pos="0.100000 0.100000 0.000000" quat="0.707107 -0.500000 0.500000 0.000000" rgba="0.800000 0.600000 0.400000 1.000000" size="0.080000 0.141421 0.000000" name="geom_agent0_aux_1_geom" type="capsule"/>
                <body pos="0.200000 0.200000 0.000000" quat="1.000000 0.000000 0.000000 0.000000" name="body_agent0_aux_1">
                    <joint armature="1.000000" damping="1.000000" axis="0.000000 0.000000 1.000000" pos="0.000000 0.000000 0.000000" range="-30.000000 30.000000" limited="true" name="joint_agent0_hip_1" type="hinge"/>
                    <geom conaffinity="0" condim="3" density="5.000000" friction="1.000000 0.500000 0.500000" pos="0.100000 0.100000 0.000000" quat="0.707107 -0.500000 0.500000 0.000000" rgba="0.800000 0.600000 0.400000 1.000000" size="0.080000 0.141421 0.000000" name="geom_agent0_left_leg_geom" type="capsule"/>
                    <body pos="0.200000 0.200000 0.000000" quat="1.000000 0.000000 0.000000 0.000000" name="body_agent0_ankle_1">
                        <joint armature="1.000000" damping="1.000000" axis="-1.000000 1.000000 0.000000" pos="0.000000 0.000000 0.000000" range="30.000000 70.000000" limited="true" name="joint_agent0_ankle_1" type="hinge"/>
                        <geom conaffinity="0" condim="3" density="5.000000" friction="1.000000 0.500000 0.500000" pos="0.200000 0.200000 0.000000" quat="0.707107 -0.500000 0.500000 0.000000" rgba="0.800000 0.600000 0.400000 1.000000" size="0.080000 0.282843 0.000000" name="geom_agent0_left_ankle_geom" type="capsule"/>
                    </body>
                </body>
            </body>
            <body pos="0.000000 0.000000 0.000000" quat="1.000000 0.000000 0.000000 0.000000" name="body_agent0_front_right_leg">
                <geom conaffinity="0" condim="3" density="5.000000" friction="1.000000 0.500000 0.500000" pos="-0.100000 0.100000 0.000000" quat="0.707107 -0.500000 -0.500000 0.000000" rgba="0.800000 0.600000 0.400000 1.000000" size="0.080000 0.141421 0.000000" name="geom_agent0_aux_2_geom" type="capsule"/>
                <body pos="-0.200000 0.200000 0.000000" quat="1.000000 0.000000 0.000000 0.000000" name="body_agent0_aux_2">
                    <joint armature="1.000000" damping="1.000000" axis="0.000000 0.000000 1.000000" pos="0.000000 0.000000 0.000000" range="-30.000000 30.000000" limited="true" name="joint_agent0_hip_2" type="hinge"/>
                    <geom conaffinity="0" condim="3" density="5.000000" friction="1.000000 0.500000 0.500000" pos="-0.100000 0.100000 0.000000" quat="0.707107 -0.500000 -0.500000 0.000000" rgba="0.800000 0.600000 0.400000 1.000000" size="0.080000 0.141421 0.000000" name="geom_agent0_right_leg_geom" type="capsule"/>
                    <body pos="-0.200000 0.200000 0.000000" quat="1.000000 0.000000 0.000000 0.000000" name="body_agent0_ankle_2">
                        <joint armature="1.000000" damping="1.000000" axis="1.000000 1.000000 0.000000" pos="0.000000 0.000000 0.000000" range="-70.000000 -30.000000" limited="true" name="joint_agent0_ankle_2" type="hinge"/>
                        <geom conaffinity="0" condim="3" density="5.000000" friction="1.000000 0.500000 0.500000" pos="-0.200000 0.200000 0.000000" quat="0.707107 -0.500000 -0.500000 0.000000" rgba="0.800000 0.600000 0.400000 1.000000" size="0.080000 0.282843 0.000000" name="geom_agent0_right_ankle_geom" type="capsule"/>
                    </body>
                </body>
            </body>
            <body pos="0.000000 0.000000 0.000000" quat="1.000000 0.000000 0.000000 0.000000" name="body_agent0_back_leg">
                <geom conaffinity="0" condim="3" density="5.000000" friction="1.000000 0.500000 0.500000" pos="-0.100000 -0.100000 0.000000" quat="0.707107 0.500000 -0.500000 0.000000" rgba="0.800000 0.600000 0.400000 1.000000" size="0.080000 0.141421 0.000000" name="geom_agent0_aux_3_geom" type="capsule"/>
                <body pos="-0.200000 -0.200000 0.000000" quat="1.000000 0.000000 0.000000 0.000000" name="body_agent0_aux_3">
                    <joint armature="1.000000" damping="1.000000" axis="0.000000 0.000000 1.000000" pos="0.000000 0.000000 0.000000" range="-30.000000 30.000000" limited="true" name="joint_agent0_hip_3" type="hinge"/>
                    <geom conaffinity="0" condim="3" density="5.000000" friction="1.000000 0.500000 0.500000" pos="-0.100000 -0.100000 0.000000" quat="0.707107 0.500000 -0.500000 0.000000" rgba="0.800000 0.600000 0.400000 1.000000" size="0.080000 0.141421 0.000000" name="geom_agent0_back_leg_geom" type="capsule"/>
                    <body pos="-0.200000 -0.200000 0.000000" quat="1.000000 0.000000 0.000000 0.000000" name="body_agent0_ankle_3">
                        <joint armature="1.000000" damping="1.000000" axis="-1.000000 1.000000 0.000000" pos="0.000000 0.000000 0.000000" range="-70.000000 -30.000000" limited="true" name="joint_agent0_ankle_3" type="hinge"/>
                        <geom conaffinity="0" condim="3" density="5.000000" friction="1.000000 0.500000 0.500000" pos="-0.200000 -0.200000 0.000000" quat="0.707107 0.500000 -0.500000 0.000000" rgba="0.800000 0.600000 0.400000 1.000000" size="0.080000 0.282843 0.000000" name="geom_agent0_third_ankle_geom" type="capsule"/>
                    </body>
                </body>
            </body>
            <body pos="0.000000 0.000000 0.000000" quat="1.000000 0.000000 0.000000 0.000000" name="body_agent0_right_back_leg">
                <geom conaffinity="0" condim="3" density="5.000000" friction="1.000000 0.500000 0.500000" pos="0.100000 -0.100000 0.000000" quat="0.707107 0.500000 0.500000 0.000000" rgba="0.800000 0.600000 0.400000 1.000000" size="0.080000 0.141421 0.000000" name="geom_agent0_aux_4_geom" type="capsule"/>
                <body pos="0.200000 -0.200000 0.000000" quat="1.000000 0.000000 0.000000 0.000000" name="body_agent0_aux_4">
                    <joint armature="1.000000" damping="1.000000" axis="0.000000 0.000000 1.000000" pos="0.000000 0.000000 0.000000" range="-30.000000 30.000000" limited="true" name="joint_agent0_hip_4" type="hinge"/>
                    <geom conaffinity="0" condim="3" density="5.000000" friction="1.000000 0.500000 0.500000" pos="0.100000 -0.100000 0.000000" quat="0.707107 0.500000 0.500000 0.000000" rgba="0.800000 0.600000 0.400000 1.000000" size="0.080000 0.141421 0.000000" name="geom_agent0_rightback_leg_geom" type="capsule"/>
                    <body pos="0.200000 -0.200000 0.000000" quat="1.000000 0.000000 0.000000 0.000000" name="body_agent0_ankle_4">
                        <joint armature="1.000000" damping="1.000000" axis="1.000000 1.000000 0.000000" pos="0.000000 0.000000 0.000000" range="30.000000 70.000000" limited="true" name="joint_agent0_ankle_4" type="hinge"/>
                        <geom conaffinity="0" condim="3" density="5.000000" friction="1.000000 0.500000 0.500000" pos="0.200000 -0.200000 0.000000" quat="0.707107 0.500000 0.500000 0.000000" rgba="0.800000 0.600000 0.400000 1.000000" size="0.080000 0.282843 0.000000" name="geom_agent0_fourth_ankle_geom" type="capsule"/>
                    </body>
                </body>
            </body>
        </body>
    </worldbody>
    <actuator>
        <motor ctrlrange="-1.000000 1.000000" gear="150.000000" ctrllimited="true" joint="joint_agent0_hip_4" name="actuator_agent0_hip_4"/>
        <motor ctrlrange="-1.000000 1.000000" gear="150.000000" ctrllimited="true" joint="joint_agent0_ankle_4" name="actuator_agent0_ankle_4"/>
        <motor ctrlrange="-1.000000 1.000000" gear="150.000000" ctrllimited="true" joint="joint_agent0_hip_1" name="actuator_agent0_hip_1"/>
        <motor ctrlrange="-1.000000 1.000000" gear="150.000000" ctrllimited="true" joint="joint_agent0_ankle_1" name="actuator_agent0_ankle_1"/>
        <motor ctrlrange="-1.000000 1.000000" gear="150.000000" ctrllimited="true" joint="joint_agent0_hip_2" name="actuator_agent0_hip_2"/>
        <motor ctrlrange="-1.000000 1.000000" gear="150.000000" ctrllimited="true" joint="joint_agent0_ankle_2" name="actuator_agent0_ankle_2"/>
        <motor ctrlrange="-1.000000 1.000000" gear="150.000000" ctrllimited="true" joint="joint_agent0_hip_3" name="actuator_agent0_hip_3"/>
        <motor ctrlrange="-1.000000 1.000000" gear="150.000000" ctrllimited="true" joint="joint_agent0_ankle_3" name="actuator_agent0_ankle_3"/>
    </actuator>
    <sensor>
        <jointpos joint="joint_agent0_hip_1" name="sensor_agent0_joint_agent0_hip_1_jointpos"/>
        <jointvel joint="joint_agent0_hip_1" name="sensor_agent0_joint_agent0_hip_1_jointvel"/>
        <jointpos joint="joint_agent0_ankle_1" name="sensor_agent0_joint_agent0_ankle_1_jointpos"/>
        <jointvel joint="joint_agent0_ankle_1" name="sensor_agent0_joint_agent0_ankle_1_jointvel"/>
        <jointpos joint="joint_agent0_hip_2" name="sensor_agent0_joint_agent0_hip_2_jointpos"/>
        <jointvel joint="joint_agent0_hip_2" name="sensor_agent0_joint_agent0_hip_2_jointvel"/>
        <jointpos joint="joint_agent0_ankle_2" name="sensor_agent0_joint_agent0_ankle_2_jointpos"/>
        <jointvel joint="joint_agent0_ankle_2" name="sensor_agent0_joint_agent0_ankle_2_jointvel"/>
        <jointpos joint="joint_agent0_hip_3" name="sensor_agent0_joint_agent0_hip_3_jointpos"/>
        <jointvel joint="joint_agent0_hip_3" name="sensor_agent0_joint_agent0_hip_3_jointvel"/>
        <jointpos joint="joint_agent0_ankle_3" name="sensor_agent0_joint_agent0_ankle_3_jointpos"/>
        <jointvel joint="joint_agent0_ankle_3" name="sensor_agent0_joint_agent0_ankle_3_jointvel"/>
        <jointpos joint="joint_agent0_hip_4" name="sensor_agent0_joint_agent0_hip_4_jointpos"/>
        <jointvel joint="joint_agent0_hip_4" name="sensor_agent0_joint_agent0_hip_4_jointvel"/>
        <jointpos joint="joint_agent0_ankle_4" name="sensor_agent0_joint_agent0_ankle_4_jointpos"/>
        <jointvel joint="joint_agent0_ankle_4" name="sensor_agent0_joint_agent0_ankle_4_jointvel"/>
        <framelinvel name="sensoragent0_body_agent0_torso_framelinvel" objname="body_agent0_torso" objtype="body"/>
        <framelinacc name="sensoragent0_body_agent0_torso_framelinacc" objname="body_agent0_torso" objtype="body"/>
        <framelinvel name="sensoragent0_body_agent0_front_left_leg_framelinvel" objname="body_agent0_front_left_leg" objtype="body"/>
        <framelinacc name="sensoragent0_body_agent0_front_left_leg_framelinacc" objname="body_agent0_front_left_leg" objtype="body"/>
        <framelinvel name="sensoragent0_body_agent0_aux_1_framelinvel" objname="body_agent0_aux_1" objtype="body"/>
        <framelinacc name="sensoragent0_body_agent0_aux_1_framelinacc" objname="body_agent0_aux_1" objtype="body"/>
        <framelinvel name="sensoragent0_body_agent0_ankle_1_framelinvel" objname="body_agent0_ankle_1" objtype="body"/>
        <framelinacc name="sensoragent0_body_agent0_ankle_1_framelinacc" objname="body_agent0_ankle_1" objtype="body"/>
        <framelinvel name="sensoragent0_body_agent0_front_right_leg_framelinvel" objname="body_agent0_front_right_leg" objtype="body"/>
        <framelinacc name="sensoragent0_body_agent0_front_right_leg_framelinacc" objname="body_agent0_front_right_leg" objtype="body"/>
        <framelinvel name="sensoragent0_body_agent0_aux_2_framelinvel" objname="body_agent0_aux_2" objtype="body"/>
        <framelinacc name="sensoragent0_body_agent0_aux_2_framelinacc" objname="body_agent0_aux_2" objtype="body"/>
        <framelinvel name="sensoragent0_body_agent0_ankle_2_framelinvel" objname="body_agent0_ankle_2" objtype="body"/>
        <framelinacc name="sensoragent0_body_agent0_ankle_2_framelinacc" objname="body_agent0_ankle_2" objtype="body"/>
        <framelinvel name="sensoragent0_body_agent0_back_leg_framelinvel" objname="body_agent0_back_leg" objtype="body"/>
        <framelinacc name="sensoragent0_body_agent0_back_leg_framelinacc" objname="body_agent0_back_leg" objtype="body"/>
        <framelinvel name="sensoragent0_body_agent0_aux_3_framelinvel" objname="body_agent0_aux_3" objtype="body"/>
        <framelinacc name="sensoragent0_body_agent0_aux_3_framelinacc" objname="body_agent0_aux_3" objtype="body"/>
        <framelinvel name="sensoragent0_body_agent0_ankle_3_framelinvel" objname="body_agent0_ankle_3" objtype="body"/>
        <framelinacc name="sensoragent0_body_agent0_ankle_3_framelinacc" objname="body_agent0_ankle_3" objtype="body"/>
        <framelinvel name="sensoragent0_body_agent0_right_back_leg_framelinvel" objname="body_agent0_right_back_leg" objtype="body"/>
        <framelinacc name="sensoragent0_body_agent0_right_back_leg_framelinacc" objname="body_agent0_right_back_leg" objtype="body"/>
        <framelinvel name="sensoragent0_body_agent0_aux_4_framelinvel" objname="body_agent0_aux_4" objtype="body"/>
        <framelinacc name="sensoragent0_body_agent0_aux_4_framelinacc" objname="body_agent0_aux_4" objtype="body"/>
        <framelinvel name="sensoragent0_body_agent0_ankle_4_framelinvel" objname="body_agent0_ankle_4" objtype="body"/>
        <framelinacc name="sensoragent0_body_agent0_ankle_4_framelinacc" objname="body_agent0_ankle_4" objtype="body"/>
    </sensor>
</mujoco>
