<mujoco>
    <include file="materials.xml"/>
    <compiler angle="degree" coordinate="local" inertiafromgeom="true"/>
    <option iterations="50" timestep="0.005000" tolerance="0.000000" cone="pyramidal" jacobian="dense" solver="Newton"/>
    <size nconmax="4000" njmax="8000"/>
    <statistic extent="2.000000" center="0.000000 0.000000 1.000000"/>
    <asset>
        <texture height="512" width="512" rgb1="0.300000 0.500000 0.700000" rgb2="0.000000 0.000000 0.000000" builtin="gradient" type="skybox"/>
        <texture height="512" width="512" markrgb="0.800000 0.800000 0.800000" rgb1="0.200000 0.300000 0.400000" rgb2="0.100000 0.150000 0.200000" builtin="checker" mark="cross" name="texplane" type="2d"/>
        <texture height="1278" width="127" random="0.010000" markrgb="1.000000 1.000000 1.000000" rgb1="0.800000 0.600000 0.400000" rgb2="0.800000 0.600000 0.400000" builtin="flat" mark="cross" name="texgeom" type="cube"/>
        <material reflectance="0.300000" texrepeat="1.000000 1.000000" name="matplane" texture="texplane" texuniform="true"/>
        <material rgba="0.800000 0.600000 0.400000 1.000000" name="matgeom" texture="texgeom" texuniform="true"/>
    </asset>
    <visual>
        <map force="0.100000" zfar="30.000000"/>
        <rgba haze="0.150000 0.250000 0.350000 1.000000"/>
        <quality shadowsize="2048"/>
        <global offheight="800" offwidth="800"/>
    </visual>
    <worldbody>
        <body pos="0.000000 0.000000 1.000000" quat="1.000000 0.000000 0.000000 0.000000" name="body_agent0_tmjcroot">
            <joint name="joint_agent0_root" type="free"/>
            <geom condim="1" pos="0.000000 0.000000 0.000000" quat="0.707107 -0.707107 0.000000 0.000000" rgba="0.700000 0.500000 0.300000 1.000000" size="0.070000 0.070000 0.000000" material="matgeom" name="geom_agent0_tmjcroot" type="capsule"/>
            <geom condim="1" pos="0.000000 0.000000 0.190000" quat="1.000000 0.000000 0.000000 0.000000" rgba="0.700000 0.500000 0.300000 1.000000" size="0.090000 0.000000 0.000000" material="matgeom" name="geom_agent0_head" type="sphere"/>
            <geom condim="1" pos="-0.010000 0.000000 -0.120000" quat="0.707107 -0.707107 0.000000 0.000000" rgba="0.700000 0.500000 0.300000 1.000000" size="0.060000 0.060000 0.000000" material="matgeom" name="geom_agent0_uwaist" type="capsule"/>
            <body pos="-0.010000 0.000000 -0.260000" quat="0.999998 0.000000 -0.002000 0.000000" name="body_agent0_lwaist">
                <joint armature="0.020000" damping="5.000000" stiffness="20.000000" axis="0.000000 0.000000 1.000000" pos="0.000000 0.000000 0.065000" range="-45.000000 45.000000" limited="true" name="joint_agent0_abdomen_z" type="hinge"/>
                <joint armature="0.020000" damping="5.000000" stiffness="10.000000" axis="0.000000 1.000000 0.000000" pos="0.000000 0.000000 0.065000" range="-75.000000 30.000000" limited="true" name="joint_agent0_abdomen_y" type="hinge"/>
                <geom condim="1" pos="0.000000 0.000000 0.000000" quat="0.707107 -0.707107 0.000000 0.000000" rgba="0.700000 0.500000 0.300000 1.000000" size="0.060000 0.060000 0.000000" material="matgeom" name="geom_agent0_lwaist" type="capsule"/>
                <body pos="0.000000 0.000000 -0.165000" quat="0.999998 0.000000 -0.002000 0.000000" name="body_agent0_pelvis">
                    <joint armature="0.020000" damping="5.000000" stiffness="10.000000" axis="1.000000 0.000000 0.000000" pos="0.000000 0.000000 0.100000" range="-35.000000 35.000000" limited="true" name="joint_agent0_abdomen_x" type="hinge"/>
                    <geom condim="1" pos="-0.020000 0.000000 0.000000" quat="0.707107 -0.707107 0.000000 0.000000" rgba="0.700000 0.500000 0.300000 1.000000" size="0.090000 0.070000 0.000000" material="matgeom" name="geom_agent0_butt" type="capsule"/>
                    <body pos="0.000000 -0.100000 -0.040000" quat="1.000000 0.000000 0.000000 0.000000" name="body_agent0_right_thigh">
                        <joint armature="0.010000" damping="5.000000" stiffness="10.000000" axis="1.000000 0.000000 0.000000" pos="0.000000 0.000000 0.000000" range="-25.000000 5.000000" limited="true" name="joint_agent0_right_hip_x" type="hinge"/>
                        <joint armature="0.010000" damping="5.000000" stiffness="10.000000" axis="0.000000 0.000000 1.000000" pos="0.000000 0.000000 0.000000" range="-60.000000 35.000000" limited="true" name="joint_agent0_right_hip_z" type="hinge"/>
                        <joint armature="0.010000" damping="5.000000" stiffness="20.000000" axis="0.000000 1.000000 0.000000" pos="0.000000 0.000000 0.000000" range="-120.000000 20.000000" limited="true" name="joint_agent0_right_hip_y" type="hinge"/>
                        <geom condim="1" pos="0.000000 0.005000 -0.170000" quat="-0.014703 0.999892 0.000000 0.000000" rgba="0.700000 0.500000 0.300000 1.000000" size="0.060000 0.170074 0.000000" material="matgeom" name="geom_agent0_right_thigh1" type="capsule"/>
                        <body pos="0.000000 0.010000 -0.403000" quat="1.000000 0.000000 0.000000 0.000000" name="body_agent0_right_shin">
                            <joint armature="0.006000" damping="1.000000" stiffness="1.000000" axis="0.000000 -1.000000 0.000000" pos="0.000000 0.000000 0.020000" range="-160.000000 -2.000000" limited="true" name="joint_agent0_right_knee" type="hinge"/>
                            <geom condim="1" pos="0.000000 0.000000 -0.150000" quat="0.000000 0.000000 1.000000 0.000000" rgba="0.700000 0.500000 0.300000 1.000000" size="0.049000 0.150000 0.000000" material="matgeom" name="geom_agent0_right_shin1" type="capsule"/>
                            <body pos="0.000000 0.000000 -0.390000" quat="1.000000 0.000000 0.000000 0.000000" name="body_agent0_right_foot">
                                <joint armature="0.000800" damping="1.000000" stiffness="4.000000" axis="0.000000 1.000000 0.000000" pos="0.000000 0.000000 0.080000" range="-50.000000 50.000000" limited="true" name="joint_agent0_right_ankle_y" type="hinge"/>
                                <joint armature="0.000600" damping="1.000000" stiffness="1.000000" axis="1.000000 0.000000 0.500000" pos="0.000000 0.000000 0.040000" range="-50.000000 50.000000" limited="true" name="joint_agent0_right_ankle_x" type="hinge"/>
                                <geom condim="1" pos="0.035000 -0.030000 0.000000" quat="0.707107 0.067040 0.703922 0.000000" rgba="0.700000 0.500000 0.300000 1.000000" size="0.027000 0.105475 0.000000" material="matgeom" name="geom_agent0_right_foot_cap1" type="capsule"/>
                                <geom condim="1" pos="0.035000 0.010000 0.000000" quat="0.707107 -0.067040 0.703922 0.000000" rgba="0.700000 0.500000 0.300000 1.000000" size="0.027000 0.105475 0.000000" material="matgeom" name="geom_agent0_right_foot_cap2" type="capsule"/>
                            </body>
                        </body>
                    </body>
                    <body pos="0.000000 0.100000 -0.040000" quat="1.000000 0.000000 0.000000 0.000000" name="body_agent0_left_thigh">
                        <joint armature="0.010000" damping="5.000000" stiffness="10.000000" axis="-1.000000 0.000000 0.000000" pos="0.000000 0.000000 0.000000" range="-25.000000 5.000000" limited="true" name="joint_agent0_left_hip_x" type="hinge"/>
                        <joint armature="0.010000" damping="5.000000" stiffness="10.000000" axis="0.000000 0.000000 -1.000000" pos="0.000000 0.000000 0.000000" range="-60.000000 35.000000" limited="true" name="joint_agent0_left_hip_z" type="hinge"/>
                        <joint armature="0.010000" damping="5.000000" stiffness="20.000000" axis="0.000000 1.000000 0.000000" pos="0.000000 0.000000 0.000000" range="-120.000000 20.000000" limited="true" name="joint_agent0_left_hip_y" type="hinge"/>
                        <geom condim="1" pos="0.000000 -0.005000 -0.170000" quat="0.014703 0.999892 0.000000 0.000000" rgba="0.700000 0.500000 0.300000 1.000000" size="0.060000 0.170074 0.000000" material="matgeom" name="geom_agent0_left_thigh1" type="capsule"/>
                        <body pos="0.000000 -0.010000 -0.403000" quat="1.000000 0.000000 0.000000 0.000000" name="body_agent0_left_shin">
                            <joint armature="0.006000" damping="1.000000" stiffness="1.000000" axis="0.000000 -1.000000 0.000000" pos="0.000000 0.000000 0.020000" range="-160.000000 -2.000000" limited="true" name="joint_agent0_left_knee" type="hinge"/>
                            <geom condim="1" pos="0.000000 0.000000 -0.150000" quat="0.000000 0.000000 1.000000 0.000000" rgba="0.700000 0.500000 0.300000 1.000000" size="0.049000 0.150000 0.000000" material="matgeom" name="geom_agent0_left_shin1" type="capsule"/>
                            <body pos="0.000000 0.000000 -0.390000" quat="1.000000 0.000000 0.000000 0.000000" name="body_agent0_left_foot">
                                <joint armature="0.000800" damping="1.000000" stiffness="4.000000" axis="0.000000 1.000000 0.000000" pos="0.000000 0.000000 0.080000" range="-50.000000 50.000000" limited="true" name="joint_agent0_left_ankle_y" type="hinge"/>
                                <joint armature="0.000600" damping="1.000000" stiffness="1.000000" axis="1.000000 0.000000 0.500000" pos="0.000000 0.000000 0.040000" range="-50.000000 50.000000" limited="true" name="joint_agent0_left_ankle_x" type="hinge"/>
                                <geom condim="1" pos="0.035000 0.030000 0.000000" quat="0.707107 -0.067040 0.703922 0.000000" rgba="0.700000 0.500000 0.300000 1.000000" size="0.027000 0.105475 0.000000" material="matgeom" name="geom_agent0_left_foot_cap1" type="capsule"/>
                                <geom condim="1" pos="0.035000 -0.010000 0.000000" quat="0.707107 0.067040 0.703922 0.000000" rgba="0.700000 0.500000 0.300000 1.000000" size="0.027000 0.105475 0.000000" material="matgeom" name="geom_agent0_left_foot_cap2" type="capsule"/>
                            </body>
                        </body>
                    </body>
                </body>
            </body>
            <body pos="0.000000 -0.170000 0.060000" quat="1.000000 0.000000 0.000000 0.000000" name="body_agent0_right_upper_arm">
                <joint armature="0.006800" damping="1.000000" stiffness="1.000000" axis="2.000000 1.000000 1.000000" pos="0.000000 0.000000 0.000000" range="-85.000000 60.000000" limited="true" name="joint_agent0_right_shoulder1" type="hinge"/>
                <joint armature="0.005100" damping="1.000000" stiffness="1.000000" axis="0.000000 -1.000000 1.000000" pos="0.000000 0.000000 0.000000" range="-85.000000 60.000000" limited="true" name="joint_agent0_right_shoulder2" type="hinge"/>
                <geom condim="1" pos="0.080000 -0.080000 -0.080000" quat="0.459701 0.627963 0.627963 0.000000" rgba="0.700000 0.500000 0.300000 1.000000" size="0.040000 0.138564 0.000000" material="matgeom" name="geom_agent0_right_uarm1" type="capsule"/>
                <body pos="0.180000 -0.180000 -0.180000" quat="1.000000 0.000000 0.000000 0.000000" name="body_agent0_right_lower_arm">
                    <joint armature="0.002800" damping="1.000000" axis="0.000000 -1.000000 1.000000" pos="0.000000 0.000000 0.000000" range="-90.000000 50.000000" limited="true" name="joint_agent0_right_elbow" type="hinge"/>
                    <geom condim="1" pos="0.090000 0.090000 0.090000" quat="0.888074 -0.325058 0.325058 0.000000" rgba="0.700000 0.500000 0.300000 1.000000" size="0.031000 0.138564 0.000000" material="matgeom" name="geom_agent0_right_larm" type="capsule"/>
                    <geom condim="1" pos="0.180000 0.180000 0.180000" quat="1.000000 0.000000 0.000000 0.000000" rgba="0.700000 0.500000 0.300000 1.000000" size="0.040000 0.000000 0.000000" material="matgeom" name="geom_agent0_right_hand" type="sphere"/>
                </body>
            </body>
            <body pos="0.000000 0.170000 0.060000" quat="1.000000 0.000000 0.000000 0.000000" name="body_agent0_left_upper_arm">
                <joint armature="0.006800" damping="1.000000" stiffness="1.000000" axis="2.000000 -1.000000 1.000000" pos="0.000000 0.000000 0.000000" range="-60.000000 85.000000" limited="true" name="joint_agent0_left_shoulder1" type="hinge"/>
                <joint armature="0.005100" damping="1.000000" stiffness="1.000000" axis="0.000000 1.000000 1.000000" pos="0.000000 0.000000 0.000000" range="-60.000000 85.000000" limited="true" name="joint_agent0_left_shoulder2" type="hinge"/>
                <geom condim="1" pos="0.080000 0.080000 -0.080000" quat="0.459701 -0.627963 0.627963 0.000000" rgba="0.700000 0.500000 0.300000 1.000000" size="0.040000 0.138564 0.000000" material="matgeom" name="geom_agent0_left_uarm1" type="capsule"/>
                <body pos="0.180000 0.180000 -0.180000" quat="1.000000 0.000000 0.000000 0.000000" name="body_agent0_left_lower_arm">
                    <joint armature="0.002800" damping="1.000000" axis="0.000000 -1.000000 -1.000000" pos="0.000000 0.000000 0.000000" range="-90.000000 50.000000" limited="true" name="joint_agent0_left_elbow" type="hinge"/>
                    <geom condim="1" pos="0.090000 -0.090000 0.090000" quat="0.888074 0.325058 0.325058 0.000000" rgba="0.700000 0.500000 0.300000 1.000000" size="0.031000 0.138564 0.000000" material="matgeom" name="geom_agent0_left_larm" type="capsule"/>
                    <geom condim="1" pos="0.180000 -0.180000 0.180000" quat="1.000000 0.000000 0.000000 0.000000" rgba="0.700000 0.500000 0.300000 1.000000" size="0.040000 0.000000 0.000000" material="matgeom" name="geom_agent0_left_hand" type="sphere"/>
                </body>
            </body>
        </body>
    </worldbody>
    <actuator>
        <motor ctrlrange="-0.400000 0.400000" gear="200.000000" ctrllimited="true" joint="joint_agent0_abdomen_y" name="actuator_agent0_abdomen_y"/>
        <motor ctrlrange="-0.400000 0.400000" gear="200.000000" ctrllimited="true" joint="joint_agent0_abdomen_z" name="actuator_agent0_abdomen_z"/>
        <motor ctrlrange="-0.400000 0.400000" gear="200.000000" ctrllimited="true" joint="joint_agent0_abdomen_x" name="actuator_agent0_abdomen_x"/>
        <motor ctrlrange="-0.400000 0.400000" gear="200.000000" ctrllimited="true" joint="joint_agent0_right_hip_x" name="actuator_agent0_right_hip_x"/>
        <motor ctrlrange="-0.400000 0.400000" gear="200.000000" ctrllimited="true" joint="joint_agent0_right_hip_z" name="actuator_agent0_right_hip_z"/>
        <motor ctrlrange="-0.400000 0.400000" gear="600.000000" ctrllimited="true" joint="joint_agent0_right_hip_y" name="actuator_agent0_right_hip_y"/>
        <motor ctrlrange="-0.400000 0.400000" gear="400.000000" ctrllimited="true" joint="joint_agent0_right_knee" name="actuator_agent0_right_knee"/>
        <motor ctrlrange="-0.400000 0.400000" gear="100.000000" ctrllimited="true" joint="joint_agent0_right_ankle_x" name="actuator_agent0_right_ankle_x"/>
        <motor ctrlrange="-0.400000 0.400000" gear="100.000000" ctrllimited="true" joint="joint_agent0_right_ankle_y" name="actuator_agent0_right_ankle_y"/>
        <motor ctrlrange="-0.400000 0.400000" gear="200.000000" ctrllimited="true" joint="joint_agent0_left_hip_x" name="actuator_agent0_left_hip_x"/>
        <motor ctrlrange="-0.400000 0.400000" gear="200.000000" ctrllimited="true" joint="joint_agent0_left_hip_z" name="actuator_agent0_left_hip_z"/>
        <motor ctrlrange="-0.400000 0.400000" gear="600.000000" ctrllimited="true" joint="joint_agent0_left_hip_y" name="actuator_agent0_left_hip_y"/>
        <motor ctrlrange="-0.400000 0.400000" gear="400.000000" ctrllimited="true" joint="joint_agent0_left_knee" name="actuator_agent0_left_knee"/>
        <motor ctrlrange="-0.400000 0.400000" gear="100.000000" ctrllimited="true" joint="joint_agent0_left_ankle_x" name="actuator_agent0_left_ankle_x"/>
        <motor ctrlrange="-0.400000 0.400000" gear="100.000000" ctrllimited="true" joint="joint_agent0_left_ankle_y" name="actuator_agent0_left_ankle_y"/>
        <motor ctrlrange="-0.400000 0.400000" gear="100.000000" ctrllimited="true" joint="joint_agent0_right_shoulder1" name="actuator_agent0_right_shoulder1"/>
        <motor ctrlrange="-0.400000 0.400000" gear="100.000000" ctrllimited="true" joint="joint_agent0_right_shoulder2" name="actuator_agent0_right_shoulder2"/>
        <motor ctrlrange="-0.400000 0.400000" gear="200.000000" ctrllimited="true" joint="joint_agent0_right_elbow" name="actuator_agent0_right_elbow"/>
        <motor ctrlrange="-0.400000 0.400000" gear="100.000000" ctrllimited="true" joint="joint_agent0_left_shoulder1" name="actuator_agent0_left_shoulder1"/>
        <motor ctrlrange="-0.400000 0.400000" gear="100.000000" ctrllimited="true" joint="joint_agent0_left_shoulder2" name="actuator_agent0_left_shoulder2"/>
        <motor ctrlrange="-0.400000 0.400000" gear="200.000000" ctrllimited="true" joint="joint_agent0_left_elbow" name="actuator_agent0_left_elbow"/>
    </actuator>
    <sensor>
        <jointpos joint="joint_agent0_abdomen_z" name="sensor_agent0_joint_agent0_abdomen_z_jointpos"/>
        <jointvel joint="joint_agent0_abdomen_z" name="sensor_agent0_joint_agent0_abdomen_z_jointvel"/>
        <jointpos joint="joint_agent0_abdomen_y" name="sensor_agent0_joint_agent0_abdomen_y_jointpos"/>
        <jointvel joint="joint_agent0_abdomen_y" name="sensor_agent0_joint_agent0_abdomen_y_jointvel"/>
        <jointpos joint="joint_agent0_abdomen_x" name="sensor_agent0_joint_agent0_abdomen_x_jointpos"/>
        <jointvel joint="joint_agent0_abdomen_x" name="sensor_agent0_joint_agent0_abdomen_x_jointvel"/>
        <jointpos joint="joint_agent0_right_hip_x" name="sensor_agent0_joint_agent0_right_hip_x_jointpos"/>
        <jointvel joint="joint_agent0_right_hip_x" name="sensor_agent0_joint_agent0_right_hip_x_jointvel"/>
        <jointpos joint="joint_agent0_right_hip_z" name="sensor_agent0_joint_agent0_right_hip_z_jointpos"/>
        <jointvel joint="joint_agent0_right_hip_z" name="sensor_agent0_joint_agent0_right_hip_z_jointvel"/>
        <jointpos joint="joint_agent0_right_hip_y" name="sensor_agent0_joint_agent0_right_hip_y_jointpos"/>
        <jointvel joint="joint_agent0_right_hip_y" name="sensor_agent0_joint_agent0_right_hip_y_jointvel"/>
        <jointpos joint="joint_agent0_right_knee" name="sensor_agent0_joint_agent0_right_knee_jointpos"/>
        <jointvel joint="joint_agent0_right_knee" name="sensor_agent0_joint_agent0_right_knee_jointvel"/>
        <jointpos joint="joint_agent0_right_ankle_y" name="sensor_agent0_joint_agent0_right_ankle_y_jointpos"/>
        <jointvel joint="joint_agent0_right_ankle_y" name="sensor_agent0_joint_agent0_right_ankle_y_jointvel"/>
        <jointpos joint="joint_agent0_right_ankle_x" name="sensor_agent0_joint_agent0_right_ankle_x_jointpos"/>
        <jointvel joint="joint_agent0_right_ankle_x" name="sensor_agent0_joint_agent0_right_ankle_x_jointvel"/>
        <jointpos joint="joint_agent0_left_hip_x" name="sensor_agent0_joint_agent0_left_hip_x_jointpos"/>
        <jointvel joint="joint_agent0_left_hip_x" name="sensor_agent0_joint_agent0_left_hip_x_jointvel"/>
        <jointpos joint="joint_agent0_left_hip_z" name="sensor_agent0_joint_agent0_left_hip_z_jointpos"/>
        <jointvel joint="joint_agent0_left_hip_z" name="sensor_agent0_joint_agent0_left_hip_z_jointvel"/>
        <jointpos joint="joint_agent0_left_hip_y" name="sensor_agent0_joint_agent0_left_hip_y_jointpos"/>
        <jointvel joint="joint_agent0_left_hip_y" name="sensor_agent0_joint_agent0_left_hip_y_jointvel"/>
        <jointpos joint="joint_agent0_left_knee" name="sensor_agent0_joint_agent0_left_knee_jointpos"/>
        <jointvel joint="joint_agent0_left_knee" name="sensor_agent0_joint_agent0_left_knee_jointvel"/>
        <jointpos joint="joint_agent0_left_ankle_y" name="sensor_agent0_joint_agent0_left_ankle_y_jointpos"/>
        <jointvel joint="joint_agent0_left_ankle_y" name="sensor_agent0_joint_agent0_left_ankle_y_jointvel"/>
        <jointpos joint="joint_agent0_left_ankle_x" name="sensor_agent0_joint_agent0_left_ankle_x_jointpos"/>
        <jointvel joint="joint_agent0_left_ankle_x" name="sensor_agent0_joint_agent0_left_ankle_x_jointvel"/>
        <jointpos joint="joint_agent0_right_shoulder1" name="sensor_agent0_joint_agent0_right_shoulder1_jointpos"/>
        <jointvel joint="joint_agent0_right_shoulder1" name="sensor_agent0_joint_agent0_right_shoulder1_jointvel"/>
        <jointpos joint="joint_agent0_right_shoulder2" name="sensor_agent0_joint_agent0_right_shoulder2_jointpos"/>
        <jointvel joint="joint_agent0_right_shoulder2" name="sensor_agent0_joint_agent0_right_shoulder2_jointvel"/>
        <jointpos joint="joint_agent0_right_elbow" name="sensor_agent0_joint_agent0_right_elbow_jointpos"/>
        <jointvel joint="joint_agent0_right_elbow" name="sensor_agent0_joint_agent0_right_elbow_jointvel"/>
        <jointpos joint="joint_agent0_left_shoulder1" name="sensor_agent0_joint_agent0_left_shoulder1_jointpos"/>
        <jointvel joint="joint_agent0_left_shoulder1" name="sensor_agent0_joint_agent0_left_shoulder1_jointvel"/>
        <jointpos joint="joint_agent0_left_shoulder2" name="sensor_agent0_joint_agent0_left_shoulder2_jointpos"/>
        <jointvel joint="joint_agent0_left_shoulder2" name="sensor_agent0_joint_agent0_left_shoulder2_jointvel"/>
        <jointpos joint="joint_agent0_left_elbow" name="sensor_agent0_joint_agent0_left_elbow_jointpos"/>
        <jointvel joint="joint_agent0_left_elbow" name="sensor_agent0_joint_agent0_left_elbow_jointvel"/>
        <framelinvel name="sensoragent0_body_agent0_tmjcroot_framelinvel" objname="body_agent0_tmjcroot" objtype="body"/>
        <framelinacc name="sensoragent0_body_agent0_tmjcroot_framelinacc" objname="body_agent0_tmjcroot" objtype="body"/>
        <framelinvel name="sensoragent0_body_agent0_lwaist_framelinvel" objname="body_agent0_lwaist" objtype="body"/>
        <framelinacc name="sensoragent0_body_agent0_lwaist_framelinacc" objname="body_agent0_lwaist" objtype="body"/>
        <framelinvel name="sensoragent0_body_agent0_pelvis_framelinvel" objname="body_agent0_pelvis" objtype="body"/>
        <framelinacc name="sensoragent0_body_agent0_pelvis_framelinacc" objname="body_agent0_pelvis" objtype="body"/>
        <framelinvel name="sensoragent0_body_agent0_right_thigh_framelinvel" objname="body_agent0_right_thigh" objtype="body"/>
        <framelinacc name="sensoragent0_body_agent0_right_thigh_framelinacc" objname="body_agent0_right_thigh" objtype="body"/>
        <framelinvel name="sensoragent0_body_agent0_right_shin_framelinvel" objname="body_agent0_right_shin" objtype="body"/>
        <framelinacc name="sensoragent0_body_agent0_right_shin_framelinacc" objname="body_agent0_right_shin" objtype="body"/>
        <framelinvel name="sensoragent0_body_agent0_right_foot_framelinvel" objname="body_agent0_right_foot" objtype="body"/>
        <framelinacc name="sensoragent0_body_agent0_right_foot_framelinacc" objname="body_agent0_right_foot" objtype="body"/>
        <framelinvel name="sensoragent0_body_agent0_left_thigh_framelinvel" objname="body_agent0_left_thigh" objtype="body"/>
        <framelinacc name="sensoragent0_body_agent0_left_thigh_framelinacc" objname="body_agent0_left_thigh" objtype="body"/>
        <framelinvel name="sensoragent0_body_agent0_left_shin_framelinvel" objname="body_agent0_left_shin" objtype="body"/>
        <framelinacc name="sensoragent0_body_agent0_left_shin_framelinacc" objname="body_agent0_left_shin" objtype="body"/>
        <framelinvel name="sensoragent0_body_agent0_left_foot_framelinvel" objname="body_agent0_left_foot" objtype="body"/>
        <framelinacc name="sensoragent0_body_agent0_left_foot_framelinacc" objname="body_agent0_left_foot" objtype="body"/>
        <framelinvel name="sensoragent0_body_agent0_right_upper_arm_framelinvel" objname="body_agent0_right_upper_arm" objtype="body"/>
        <framelinacc name="sensoragent0_body_agent0_right_upper_arm_framelinacc" objname="body_agent0_right_upper_arm" objtype="body"/>
        <framelinvel name="sensoragent0_body_agent0_right_lower_arm_framelinvel" objname="body_agent0_right_lower_arm" objtype="body"/>
        <framelinacc name="sensoragent0_body_agent0_right_lower_arm_framelinacc" objname="body_agent0_right_lower_arm" objtype="body"/>
        <framelinvel name="sensoragent0_body_agent0_left_upper_arm_framelinvel" objname="body_agent0_left_upper_arm" objtype="body"/>
        <framelinacc name="sensoragent0_body_agent0_left_upper_arm_framelinacc" objname="body_agent0_left_upper_arm" objtype="body"/>
        <framelinvel name="sensoragent0_body_agent0_left_lower_arm_framelinvel" objname="body_agent0_left_lower_arm" objtype="body"/>
        <framelinacc name="sensoragent0_body_agent0_left_lower_arm_framelinacc" objname="body_agent0_left_lower_arm" objtype="body"/>
    </sensor>
    <worldbody>
        <body pos="0.000000 0.000000 0.000000" quat="0.000000 0.000000 0.000000 1.000000" name="tGen_terrainGen0_0">
            <geom conaffinity="1" contype="0" pos="0.000000 0.000000 0.000000" quat="1.000000 0.000000 0.000000 0.000000" size="10.000000 10.000000 0.100000" name="tGen_terrainGen0_0" type="plane"/>
        </body>
        <body pos="0.000000 0.000000 101.025002" quat="1.000000 0.000000 0.000000 0.000000" name="tGen_terrainGen0_1">
            <geom conaffinity="1" contype="0" pos="0.000000 0.000000 0.000000" quat="1.000000 0.000000 0.000000 0.000000" size="0.250000 1.000000 0.012500" name="tGen_terrainGen0_1" type="box"/>
        </body>
        <body pos="0.000000 0.000000 102.050003" quat="1.000000 0.000000 0.000000 0.000000" name="tGen_terrainGen0_3">
            <geom conaffinity="1" contype="0" pos="0.000000 0.000000 0.000000" quat="1.000000 0.000000 0.000000 0.000000" size="0.250000 1.000000 0.012500" name="tGen_terrainGen0_3" type="box"/>
        </body>
        <body pos="0.000000 0.000000 103.074997" quat="1.000000 0.000000 0.000000 0.000000" name="tGen_terrainGen0_5">
            <geom conaffinity="1" contype="0" pos="0.000000 0.000000 0.000000" quat="1.000000 0.000000 0.000000 0.000000" size="0.250000 1.000000 0.012500" name="tGen_terrainGen0_5" type="box"/>
        </body>
        <body pos="0.000000 0.000000 104.099998" quat="1.000000 0.000000 0.000000 0.000000" name="tGen_terrainGen0_7">
            <geom conaffinity="1" contype="0" pos="0.000000 0.000000 0.000000" quat="1.000000 0.000000 0.000000 0.000000" size="0.250000 1.000000 0.012500" name="tGen_terrainGen0_7" type="box"/>
        </body>
        <body pos="0.000000 0.000000 105.125000" quat="1.000000 0.000000 0.000000 0.000000" name="tGen_terrainGen0_9">
            <geom conaffinity="1" contype="0" pos="0.000000 0.000000 0.000000" quat="1.000000 0.000000 0.000000 0.000000" size="0.250000 1.000000 0.012500" name="tGen_terrainGen0_9" type="box"/>
        </body>
        <body pos="0.000000 0.000000 106.150002" quat="1.000000 0.000000 0.000000 0.000000" name="tGen_terrainGen0_11">
            <geom conaffinity="1" contype="0" pos="0.000000 0.000000 0.000000" quat="1.000000 0.000000 0.000000 0.000000" size="0.250000 1.000000 0.012500" name="tGen_terrainGen0_11" type="box"/>
        </body>
        <body pos="0.000000 0.000000 107.175003" quat="1.000000 0.000000 0.000000 0.000000" name="tGen_terrainGen0_13">
            <geom conaffinity="1" contype="0" pos="0.000000 0.000000 0.000000" quat="1.000000 0.000000 0.000000 0.000000" size="0.250000 1.000000 0.012500" name="tGen_terrainGen0_13" type="box"/>
        </body>
        <body pos="0.000000 0.000000 108.199997" quat="1.000000 0.000000 0.000000 0.000000" name="tGen_terrainGen0_15">
            <geom conaffinity="1" contype="0" pos="0.000000 0.000000 0.000000" quat="1.000000 0.000000 0.000000 0.000000" size="0.250000 1.000000 0.012500" name="tGen_terrainGen0_15" type="box"/>
        </body>
        <body pos="0.000000 0.000000 109.224998" quat="1.000000 0.000000 0.000000 0.000000" name="tGen_terrainGen0_17">
            <geom conaffinity="1" contype="0" pos="0.000000 0.000000 0.000000" quat="1.000000 0.000000 0.000000 0.000000" size="0.250000 1.000000 0.012500" name="tGen_terrainGen0_17" type="box"/>
        </body>
        <body pos="0.000000 0.000000 110.250000" quat="1.000000 0.000000 0.000000 0.000000" name="tGen_terrainGen0_19">
            <geom conaffinity="1" contype="0" pos="0.000000 0.000000 0.000000" quat="1.000000 0.000000 0.000000 0.000000" size="0.250000 1.000000 0.012500" name="tGen_terrainGen0_19" type="box"/>
        </body>
        <body pos="0.000000 0.000000 111.275002" quat="1.000000 0.000000 0.000000 0.000000" name="tGen_terrainGen0_21">
            <geom conaffinity="1" contype="0" pos="0.000000 0.000000 0.000000" quat="1.000000 0.000000 0.000000 0.000000" size="0.250000 1.000000 0.012500" name="tGen_terrainGen0_21" type="box"/>
        </body>
        <body pos="0.000000 0.000000 112.300003" quat="1.000000 0.000000 0.000000 0.000000" name="tGen_terrainGen0_23">
            <geom conaffinity="1" contype="0" pos="0.000000 0.000000 0.000000" quat="1.000000 0.000000 0.000000 0.000000" size="0.250000 1.000000 0.012500" name="tGen_terrainGen0_23" type="box"/>
        </body>
        <body pos="0.000000 0.000000 113.324997" quat="1.000000 0.000000 0.000000 0.000000" name="tGen_terrainGen0_25">
            <geom conaffinity="1" contype="0" pos="0.000000 0.000000 0.000000" quat="1.000000 0.000000 0.000000 0.000000" size="0.250000 1.000000 0.012500" name="tGen_terrainGen0_25" type="box"/>
        </body>
        <body pos="0.000000 0.000000 114.349998" quat="1.000000 0.000000 0.000000 0.000000" name="tGen_terrainGen0_27">
            <geom conaffinity="1" contype="0" pos="0.000000 0.000000 0.000000" quat="1.000000 0.000000 0.000000 0.000000" size="0.250000 1.000000 0.012500" name="tGen_terrainGen0_27" type="box"/>
        </body>
        <body pos="0.000000 0.000000 115.375000" quat="1.000000 0.000000 0.000000 0.000000" name="tGen_terrainGen0_29">
            <geom conaffinity="1" contype="0" pos="0.000000 0.000000 0.000000" quat="1.000000 0.000000 0.000000 0.000000" size="0.250000 1.000000 0.012500" name="tGen_terrainGen0_29" type="box"/>
        </body>
        <body pos="0.000000 0.000000 116.400002" quat="1.000000 0.000000 0.000000 0.000000" name="tGen_terrainGen0_31">
            <geom conaffinity="1" contype="0" pos="0.000000 0.000000 0.000000" quat="1.000000 0.000000 0.000000 0.000000" size="0.250000 1.000000 0.012500" name="tGen_terrainGen0_31" type="box"/>
        </body>
        <body pos="0.000000 0.000000 117.425003" quat="1.000000 0.000000 0.000000 0.000000" name="tGen_terrainGen0_33">
            <geom conaffinity="1" contype="0" pos="0.000000 0.000000 0.000000" quat="1.000000 0.000000 0.000000 0.000000" size="0.250000 1.000000 0.012500" name="tGen_terrainGen0_33" type="box"/>
        </body>
        <body pos="0.000000 0.000000 118.449997" quat="1.000000 0.000000 0.000000 0.000000" name="tGen_terrainGen0_35">
            <geom conaffinity="1" contype="0" pos="0.000000 0.000000 0.000000" quat="1.000000 0.000000 0.000000 0.000000" size="0.250000 1.000000 0.012500" name="tGen_terrainGen0_35" type="box"/>
        </body>
        <body pos="0.000000 0.000000 119.474998" quat="1.000000 0.000000 0.000000 0.000000" name="tGen_terrainGen0_37">
            <geom conaffinity="1" contype="0" pos="0.000000 0.000000 0.000000" quat="1.000000 0.000000 0.000000 0.000000" size="0.250000 1.000000 0.012500" name="tGen_terrainGen0_37" type="box"/>
        </body>
        <body pos="0.000000 0.000000 120.500000" quat="1.000000 0.000000 0.000000 0.000000" name="tGen_terrainGen0_39">
            <geom conaffinity="1" contype="0" pos="0.000000 0.000000 0.000000" quat="1.000000 0.000000 0.000000 0.000000" size="0.250000 1.000000 0.012500" name="tGen_terrainGen0_39" type="box"/>
        </body>
        <body pos="0.000000 0.000000 121.525002" quat="1.000000 0.000000 0.000000 0.000000" name="tGen_terrainGen0_41">
            <geom conaffinity="1" contype="0" pos="0.000000 0.000000 0.000000" quat="1.000000 0.000000 0.000000 0.000000" size="0.250000 1.000000 0.012500" name="tGen_terrainGen0_41" type="box"/>
        </body>
        <body pos="0.000000 0.000000 122.550003" quat="1.000000 0.000000 0.000000 0.000000" name="tGen_terrainGen0_43">
            <geom conaffinity="1" contype="0" pos="0.000000 0.000000 0.000000" quat="1.000000 0.000000 0.000000 0.000000" size="0.250000 1.000000 0.012500" name="tGen_terrainGen0_43" type="box"/>
        </body>
        <body pos="0.000000 0.000000 123.574997" quat="1.000000 0.000000 0.000000 0.000000" name="tGen_terrainGen0_45">
            <geom conaffinity="1" contype="0" pos="0.000000 0.000000 0.000000" quat="1.000000 0.000000 0.000000 0.000000" size="0.250000 1.000000 0.012500" name="tGen_terrainGen0_45" type="box"/>
        </body>
        <body pos="0.000000 0.000000 124.599998" quat="1.000000 0.000000 0.000000 0.000000" name="tGen_terrainGen0_47">
            <geom conaffinity="1" contype="0" pos="0.000000 0.000000 0.000000" quat="1.000000 0.000000 0.000000 0.000000" size="0.250000 1.000000 0.012500" name="tGen_terrainGen0_47" type="box"/>
        </body>
        <body pos="0.000000 0.000000 125.625000" quat="1.000000 0.000000 0.000000 0.000000" name="tGen_terrainGen0_49">
            <geom conaffinity="1" contype="0" pos="0.000000 0.000000 0.000000" quat="1.000000 0.000000 0.000000 0.000000" size="0.250000 1.000000 0.012500" name="tGen_terrainGen0_49" type="box"/>
        </body>
        <body pos="0.000000 0.000000 126.650002" quat="1.000000 0.000000 0.000000 0.000000" name="tGen_terrainGen0_51">
            <geom conaffinity="1" contype="0" pos="0.000000 0.000000 0.000000" quat="1.000000 0.000000 0.000000 0.000000" size="0.250000 1.000000 0.012500" name="tGen_terrainGen0_51" type="box"/>
        </body>
        <body pos="0.000000 0.000000 127.675003" quat="1.000000 0.000000 0.000000 0.000000" name="tGen_terrainGen0_53">
            <geom conaffinity="1" contype="0" pos="0.000000 0.000000 0.000000" quat="1.000000 0.000000 0.000000 0.000000" size="0.250000 1.000000 0.012500" name="tGen_terrainGen0_53" type="box"/>
        </body>
        <body pos="0.000000 0.000000 128.699997" quat="1.000000 0.000000 0.000000 0.000000" name="tGen_terrainGen0_55">
            <geom conaffinity="1" contype="0" pos="0.000000 0.000000 0.000000" quat="1.000000 0.000000 0.000000 0.000000" size="0.250000 1.000000 0.012500" name="tGen_terrainGen0_55" type="box"/>
        </body>
        <body pos="0.000000 0.000000 129.725006" quat="1.000000 0.000000 0.000000 0.000000" name="tGen_terrainGen0_57">
            <geom conaffinity="1" contype="0" pos="0.000000 0.000000 0.000000" quat="1.000000 0.000000 0.000000 0.000000" size="0.250000 1.000000 0.012500" name="tGen_terrainGen0_57" type="box"/>
        </body>
        <body pos="0.000000 0.000000 130.750000" quat="1.000000 0.000000 0.000000 0.000000" name="tGen_terrainGen0_59">
            <geom conaffinity="1" contype="0" pos="0.000000 0.000000 0.000000" quat="1.000000 0.000000 0.000000 0.000000" size="0.250000 1.000000 0.012500" name="tGen_terrainGen0_59" type="box"/>
        </body>
        <body pos="0.000000 0.000000 131.774994" quat="1.000000 0.000000 0.000000 0.000000" name="tGen_terrainGen0_61">
            <geom conaffinity="1" contype="0" pos="0.000000 0.000000 0.000000" quat="1.000000 0.000000 0.000000 0.000000" size="0.250000 1.000000 0.012500" name="tGen_terrainGen0_61" type="box"/>
        </body>
        <body pos="0.000000 0.000000 132.800003" quat="1.000000 0.000000 0.000000 0.000000" name="tGen_terrainGen0_63">
            <geom conaffinity="1" contype="0" pos="0.000000 0.000000 0.000000" quat="1.000000 0.000000 0.000000 0.000000" size="0.250000 1.000000 0.012500" name="tGen_terrainGen0_63" type="box"/>
        </body>
        <body pos="0.000000 0.000000 133.824997" quat="1.000000 0.000000 0.000000 0.000000" name="tGen_terrainGen0_65">
            <geom conaffinity="1" contype="0" pos="0.000000 0.000000 0.000000" quat="1.000000 0.000000 0.000000 0.000000" size="0.250000 1.000000 0.012500" name="tGen_terrainGen0_65" type="box"/>
        </body>
        <body pos="0.000000 0.000000 134.850006" quat="1.000000 0.000000 0.000000 0.000000" name="tGen_terrainGen0_67">
            <geom conaffinity="1" contype="0" pos="0.000000 0.000000 0.000000" quat="1.000000 0.000000 0.000000 0.000000" size="0.250000 1.000000 0.012500" name="tGen_terrainGen0_67" type="box"/>
        </body>
        <body pos="0.000000 0.000000 135.875000" quat="1.000000 0.000000 0.000000 0.000000" name="tGen_terrainGen0_69">
            <geom conaffinity="1" contype="0" pos="0.000000 0.000000 0.000000" quat="1.000000 0.000000 0.000000 0.000000" size="0.250000 1.000000 0.012500" name="tGen_terrainGen0_69" type="box"/>
        </body>
        <body pos="0.000000 0.000000 136.899994" quat="1.000000 0.000000 0.000000 0.000000" name="tGen_terrainGen0_71">
            <geom conaffinity="1" contype="0" pos="0.000000 0.000000 0.000000" quat="1.000000 0.000000 0.000000 0.000000" size="0.250000 1.000000 0.012500" name="tGen_terrainGen0_71" type="box"/>
        </body>
        <body pos="0.000000 0.000000 137.925003" quat="1.000000 0.000000 0.000000 0.000000" name="tGen_terrainGen0_73">
            <geom conaffinity="1" contype="0" pos="0.000000 0.000000 0.000000" quat="1.000000 0.000000 0.000000 0.000000" size="0.250000 1.000000 0.012500" name="tGen_terrainGen0_73" type="box"/>
        </body>
        <body pos="0.000000 0.000000 138.949997" quat="1.000000 0.000000 0.000000 0.000000" name="tGen_terrainGen0_75">
            <geom conaffinity="1" contype="0" pos="0.000000 0.000000 0.000000" quat="1.000000 0.000000 0.000000 0.000000" size="0.250000 1.000000 0.012500" name="tGen_terrainGen0_75" type="box"/>
        </body>
        <body pos="0.000000 0.000000 139.975006" quat="1.000000 0.000000 0.000000 0.000000" name="tGen_terrainGen0_77">
            <geom conaffinity="1" contype="0" pos="0.000000 0.000000 0.000000" quat="1.000000 0.000000 0.000000 0.000000" size="0.250000 1.000000 0.012500" name="tGen_terrainGen0_77" type="box"/>
        </body>
        <body pos="0.000000 0.000000 141.000000" quat="1.000000 0.000000 0.000000 0.000000" name="tGen_terrainGen0_79">
            <geom conaffinity="1" contype="0" pos="0.000000 0.000000 0.000000" quat="1.000000 0.000000 0.000000 0.000000" size="0.250000 1.000000 0.012500" name="tGen_terrainGen0_79" type="box"/>
        </body>
        <body pos="0.000000 0.000000 142.024994" quat="1.000000 0.000000 0.000000 0.000000" name="tGen_terrainGen0_81">
            <geom conaffinity="1" contype="0" pos="0.000000 0.000000 0.000000" quat="1.000000 0.000000 0.000000 0.000000" size="0.250000 1.000000 0.012500" name="tGen_terrainGen0_81" type="box"/>
        </body>
        <body pos="0.000000 0.000000 143.050003" quat="1.000000 0.000000 0.000000 0.000000" name="tGen_terrainGen0_83">
            <geom conaffinity="1" contype="0" pos="0.000000 0.000000 0.000000" quat="1.000000 0.000000 0.000000 0.000000" size="0.250000 1.000000 0.012500" name="tGen_terrainGen0_83" type="box"/>
        </body>
        <body pos="0.000000 0.000000 144.074997" quat="1.000000 0.000000 0.000000 0.000000" name="tGen_terrainGen0_85">
            <geom conaffinity="1" contype="0" pos="0.000000 0.000000 0.000000" quat="1.000000 0.000000 0.000000 0.000000" size="0.250000 1.000000 0.012500" name="tGen_terrainGen0_85" type="box"/>
        </body>
        <body pos="0.000000 0.000000 145.100006" quat="1.000000 0.000000 0.000000 0.000000" name="tGen_terrainGen0_87">
            <geom conaffinity="1" contype="0" pos="0.000000 0.000000 0.000000" quat="1.000000 0.000000 0.000000 0.000000" size="0.250000 1.000000 0.012500" name="tGen_terrainGen0_87" type="box"/>
        </body>
        <body pos="0.000000 0.000000 146.125000" quat="1.000000 0.000000 0.000000 0.000000" name="tGen_terrainGen0_89">
            <geom conaffinity="1" contype="0" pos="0.000000 0.000000 0.000000" quat="1.000000 0.000000 0.000000 0.000000" size="0.250000 1.000000 0.012500" name="tGen_terrainGen0_89" type="box"/>
        </body>
        <body pos="0.000000 0.000000 147.149994" quat="1.000000 0.000000 0.000000 0.000000" name="tGen_terrainGen0_91">
            <geom conaffinity="1" contype="0" pos="0.000000 0.000000 0.000000" quat="1.000000 0.000000 0.000000 0.000000" size="0.250000 1.000000 0.012500" name="tGen_terrainGen0_91" type="box"/>
        </body>
        <body pos="0.000000 0.000000 148.175003" quat="1.000000 0.000000 0.000000 0.000000" name="tGen_terrainGen0_93">
            <geom conaffinity="1" contype="0" pos="0.000000 0.000000 0.000000" quat="1.000000 0.000000 0.000000 0.000000" size="0.250000 1.000000 0.012500" name="tGen_terrainGen0_93" type="box"/>
        </body>
        <body pos="0.000000 0.000000 149.199997" quat="1.000000 0.000000 0.000000 0.000000" name="tGen_terrainGen0_95">
            <geom conaffinity="1" contype="0" pos="0.000000 0.000000 0.000000" quat="1.000000 0.000000 0.000000 0.000000" size="0.250000 1.000000 0.012500" name="tGen_terrainGen0_95" type="box"/>
        </body>
        <body pos="0.000000 0.000000 150.225006" quat="1.000000 0.000000 0.000000 0.000000" name="tGen_terrainGen0_97">
            <geom conaffinity="1" contype="0" pos="0.000000 0.000000 0.000000" quat="1.000000 0.000000 0.000000 0.000000" size="0.250000 1.000000 0.012500" name="tGen_terrainGen0_97" type="box"/>
        </body>
        <body pos="0.000000 0.000000 151.250000" quat="1.000000 0.000000 0.000000 0.000000" name="tGen_terrainGen0_99">
            <geom conaffinity="1" contype="0" pos="0.000000 0.000000 0.000000" quat="1.000000 0.000000 0.000000 0.000000" size="0.250000 1.000000 0.012500" name="tGen_terrainGen0_99" type="box"/>
        </body>
        <body pos="0.000000 0.000000 152.274994" quat="1.000000 0.000000 0.000000 0.000000" name="tGen_terrainGen0_101">
            <geom conaffinity="1" contype="0" pos="0.000000 0.000000 0.000000" quat="1.000000 0.000000 0.000000 0.000000" size="0.250000 1.000000 0.012500" name="tGen_terrainGen0_101" type="box"/>
        </body>
        <body pos="0.000000 0.000000 153.300003" quat="1.000000 0.000000 0.000000 0.000000" name="tGen_terrainGen0_103">
            <geom conaffinity="1" contype="0" pos="0.000000 0.000000 0.000000" quat="1.000000 0.000000 0.000000 0.000000" size="0.250000 1.000000 0.012500" name="tGen_terrainGen0_103" type="box"/>
        </body>
        <body pos="0.000000 0.000000 154.324997" quat="1.000000 0.000000 0.000000 0.000000" name="tGen_terrainGen0_105">
            <geom conaffinity="1" contype="0" pos="0.000000 0.000000 0.000000" quat="1.000000 0.000000 0.000000 0.000000" size="0.250000 1.000000 0.012500" name="tGen_terrainGen0_105" type="box"/>
        </body>
        <body pos="0.000000 0.000000 155.350006" quat="1.000000 0.000000 0.000000 0.000000" name="tGen_terrainGen0_107">
            <geom conaffinity="1" contype="0" pos="0.000000 0.000000 0.000000" quat="1.000000 0.000000 0.000000 0.000000" size="0.250000 1.000000 0.012500" name="tGen_terrainGen0_107" type="box"/>
        </body>
        <body pos="0.000000 0.000000 156.375000" quat="1.000000 0.000000 0.000000 0.000000" name="tGen_terrainGen0_109">
            <geom conaffinity="1" contype="0" pos="0.000000 0.000000 0.000000" quat="1.000000 0.000000 0.000000 0.000000" size="0.250000 1.000000 0.012500" name="tGen_terrainGen0_109" type="box"/>
        </body>
        <body pos="0.000000 0.000000 157.399994" quat="1.000000 0.000000 0.000000 0.000000" name="tGen_terrainGen0_111">
            <geom conaffinity="1" contype="0" pos="0.000000 0.000000 0.000000" quat="1.000000 0.000000 0.000000 0.000000" size="0.250000 1.000000 0.012500" name="tGen_terrainGen0_111" type="box"/>
        </body>
        <body pos="0.000000 0.000000 158.425003" quat="1.000000 0.000000 0.000000 0.000000" name="tGen_terrainGen0_113">
            <geom conaffinity="1" contype="0" pos="0.000000 0.000000 0.000000" quat="1.000000 0.000000 0.000000 0.000000" size="0.250000 1.000000 0.012500" name="tGen_terrainGen0_113" type="box"/>
        </body>
        <body pos="0.000000 0.000000 159.449997" quat="1.000000 0.000000 0.000000 0.000000" name="tGen_terrainGen0_115">
            <geom conaffinity="1" contype="0" pos="0.000000 0.000000 0.000000" quat="1.000000 0.000000 0.000000 0.000000" size="0.250000 1.000000 0.012500" name="tGen_terrainGen0_115" type="box"/>
        </body>
        <body pos="0.000000 0.000000 160.475006" quat="1.000000 0.000000 0.000000 0.000000" name="tGen_terrainGen0_117">
            <geom conaffinity="1" contype="0" pos="0.000000 0.000000 0.000000" quat="1.000000 0.000000 0.000000 0.000000" size="0.250000 1.000000 0.012500" name="tGen_terrainGen0_117" type="box"/>
        </body>
        <body pos="0.000000 0.000000 161.500000" quat="1.000000 0.000000 0.000000 0.000000" name="tGen_terrainGen0_119">
            <geom conaffinity="1" contype="0" pos="0.000000 0.000000 0.000000" quat="1.000000 0.000000 0.000000 0.000000" size="0.250000 1.000000 0.012500" name="tGen_terrainGen0_119" type="box"/>
        </body>
        <body pos="0.000000 0.000000 162.524994" quat="1.000000 0.000000 0.000000 0.000000" name="tGen_terrainGen0_121">
            <geom conaffinity="1" contype="0" pos="0.000000 0.000000 0.000000" quat="1.000000 0.000000 0.000000 0.000000" size="0.250000 1.000000 0.012500" name="tGen_terrainGen0_121" type="box"/>
        </body>
        <body pos="0.000000 0.000000 163.550003" quat="1.000000 0.000000 0.000000 0.000000" name="tGen_terrainGen0_123">
            <geom conaffinity="1" contype="0" pos="0.000000 0.000000 0.000000" quat="1.000000 0.000000 0.000000 0.000000" size="0.250000 1.000000 0.012500" name="tGen_terrainGen0_123" type="box"/>
        </body>
        <body pos="0.000000 0.000000 164.574997" quat="1.000000 0.000000 0.000000 0.000000" name="tGen_terrainGen0_125">
            <geom conaffinity="1" contype="0" pos="0.000000 0.000000 0.000000" quat="1.000000 0.000000 0.000000 0.000000" size="0.250000 1.000000 0.012500" name="tGen_terrainGen0_125" type="box"/>
        </body>
        <body pos="0.000000 0.000000 165.600006" quat="1.000000 0.000000 0.000000 0.000000" name="tGen_terrainGen0_127">
            <geom conaffinity="1" contype="0" pos="0.000000 0.000000 0.000000" quat="1.000000 0.000000 0.000000 0.000000" size="0.250000 1.000000 0.012500" name="tGen_terrainGen0_127" type="box"/>
        </body>
        <body pos="0.000000 0.000000 166.625000" quat="1.000000 0.000000 0.000000 0.000000" name="tGen_terrainGen0_129">
            <geom conaffinity="1" contype="0" pos="0.000000 0.000000 0.000000" quat="1.000000 0.000000 0.000000 0.000000" size="0.250000 1.000000 0.012500" name="tGen_terrainGen0_129" type="box"/>
        </body>
        <body pos="0.000000 0.000000 167.649994" quat="1.000000 0.000000 0.000000 0.000000" name="tGen_terrainGen0_131">
            <geom conaffinity="1" contype="0" pos="0.000000 0.000000 0.000000" quat="1.000000 0.000000 0.000000 0.000000" size="0.250000 1.000000 0.012500" name="tGen_terrainGen0_131" type="box"/>
        </body>
        <body pos="0.000000 0.000000 168.674988" quat="1.000000 0.000000 0.000000 0.000000" name="tGen_terrainGen0_133">
            <geom conaffinity="1" contype="0" pos="0.000000 0.000000 0.000000" quat="1.000000 0.000000 0.000000 0.000000" size="0.250000 1.000000 0.012500" name="tGen_terrainGen0_133" type="box"/>
        </body>
        <body pos="0.000000 0.000000 169.699997" quat="1.000000 0.000000 0.000000 0.000000" name="tGen_terrainGen0_135">
            <geom conaffinity="1" contype="0" pos="0.000000 0.000000 0.000000" quat="1.000000 0.000000 0.000000 0.000000" size="0.250000 1.000000 0.012500" name="tGen_terrainGen0_135" type="box"/>
        </body>
        <body pos="0.000000 0.000000 170.725006" quat="1.000000 0.000000 0.000000 0.000000" name="tGen_terrainGen0_137">
            <geom conaffinity="1" contype="0" pos="0.000000 0.000000 0.000000" quat="1.000000 0.000000 0.000000 0.000000" size="0.250000 1.000000 0.012500" name="tGen_terrainGen0_137" type="box"/>
        </body>
        <body pos="0.000000 0.000000 171.750000" quat="1.000000 0.000000 0.000000 0.000000" name="tGen_terrainGen0_139">
            <geom conaffinity="1" contype="0" pos="0.000000 0.000000 0.000000" quat="1.000000 0.000000 0.000000 0.000000" size="0.250000 1.000000 0.012500" name="tGen_terrainGen0_139" type="box"/>
        </body>
        <body pos="0.000000 0.000000 172.774994" quat="1.000000 0.000000 0.000000 0.000000" name="tGen_terrainGen0_141">
            <geom conaffinity="1" contype="0" pos="0.000000 0.000000 0.000000" quat="1.000000 0.000000 0.000000 0.000000" size="0.250000 1.000000 0.012500" name="tGen_terrainGen0_141" type="box"/>
        </body>
        <body pos="0.000000 0.000000 173.799988" quat="1.000000 0.000000 0.000000 0.000000" name="tGen_terrainGen0_143">
            <geom conaffinity="1" contype="0" pos="0.000000 0.000000 0.000000" quat="1.000000 0.000000 0.000000 0.000000" size="0.250000 1.000000 0.012500" name="tGen_terrainGen0_143" type="box"/>
        </body>
        <body pos="0.000000 0.000000 174.824997" quat="1.000000 0.000000 0.000000 0.000000" name="tGen_terrainGen0_145">
            <geom conaffinity="1" contype="0" pos="0.000000 0.000000 0.000000" quat="1.000000 0.000000 0.000000 0.000000" size="0.250000 1.000000 0.012500" name="tGen_terrainGen0_145" type="box"/>
        </body>
        <body pos="0.000000 0.000000 175.850006" quat="1.000000 0.000000 0.000000 0.000000" name="tGen_terrainGen0_147">
            <geom conaffinity="1" contype="0" pos="0.000000 0.000000 0.000000" quat="1.000000 0.000000 0.000000 0.000000" size="0.250000 1.000000 0.012500" name="tGen_terrainGen0_147" type="box"/>
        </body>
        <body pos="0.000000 0.000000 176.875000" quat="1.000000 0.000000 0.000000 0.000000" name="tGen_terrainGen0_149">
            <geom conaffinity="1" contype="0" pos="0.000000 0.000000 0.000000" quat="1.000000 0.000000 0.000000 0.000000" size="0.250000 1.000000 0.012500" name="tGen_terrainGen0_149" type="box"/>
        </body>
        <body pos="0.000000 0.000000 177.899994" quat="1.000000 0.000000 0.000000 0.000000" name="tGen_terrainGen0_151">
            <geom conaffinity="1" contype="0" pos="0.000000 0.000000 0.000000" quat="1.000000 0.000000 0.000000 0.000000" size="0.250000 1.000000 0.012500" name="tGen_terrainGen0_151" type="box"/>
        </body>
        <body pos="0.000000 0.000000 178.924988" quat="1.000000 0.000000 0.000000 0.000000" name="tGen_terrainGen0_153">
            <geom conaffinity="1" contype="0" pos="0.000000 0.000000 0.000000" quat="1.000000 0.000000 0.000000 0.000000" size="0.250000 1.000000 0.012500" name="tGen_terrainGen0_153" type="box"/>
        </body>
        <body pos="0.000000 0.000000 179.949997" quat="1.000000 0.000000 0.000000 0.000000" name="tGen_terrainGen0_155">
            <geom conaffinity="1" contype="0" pos="0.000000 0.000000 0.000000" quat="1.000000 0.000000 0.000000 0.000000" size="0.250000 1.000000 0.012500" name="tGen_terrainGen0_155" type="box"/>
        </body>
        <body pos="0.000000 0.000000 180.975006" quat="1.000000 0.000000 0.000000 0.000000" name="tGen_terrainGen0_157">
            <geom conaffinity="1" contype="0" pos="0.000000 0.000000 0.000000" quat="1.000000 0.000000 0.000000 0.000000" size="0.250000 1.000000 0.012500" name="tGen_terrainGen0_157" type="box"/>
        </body>
        <body pos="0.000000 0.000000 182.000000" quat="1.000000 0.000000 0.000000 0.000000" name="tGen_terrainGen0_159">
            <geom conaffinity="1" contype="0" pos="0.000000 0.000000 0.000000" quat="1.000000 0.000000 0.000000 0.000000" size="0.250000 1.000000 0.012500" name="tGen_terrainGen0_159" type="box"/>
        </body>
        <body pos="0.000000 0.000000 183.024994" quat="1.000000 0.000000 0.000000 0.000000" name="tGen_terrainGen0_161">
            <geom conaffinity="1" contype="0" pos="0.000000 0.000000 0.000000" quat="1.000000 0.000000 0.000000 0.000000" size="0.250000 1.000000 0.012500" name="tGen_terrainGen0_161" type="box"/>
        </body>
        <body pos="0.000000 0.000000 184.049988" quat="1.000000 0.000000 0.000000 0.000000" name="tGen_terrainGen0_163">
            <geom conaffinity="1" contype="0" pos="0.000000 0.000000 0.000000" quat="1.000000 0.000000 0.000000 0.000000" size="0.250000 1.000000 0.012500" name="tGen_terrainGen0_163" type="box"/>
        </body>
        <body pos="0.000000 0.000000 185.074997" quat="1.000000 0.000000 0.000000 0.000000" name="tGen_terrainGen0_165">
            <geom conaffinity="1" contype="0" pos="0.000000 0.000000 0.000000" quat="1.000000 0.000000 0.000000 0.000000" size="0.250000 1.000000 0.012500" name="tGen_terrainGen0_165" type="box"/>
        </body>
        <body pos="0.000000 0.000000 186.100006" quat="1.000000 0.000000 0.000000 0.000000" name="tGen_terrainGen0_167">
            <geom conaffinity="1" contype="0" pos="0.000000 0.000000 0.000000" quat="1.000000 0.000000 0.000000 0.000000" size="0.250000 1.000000 0.012500" name="tGen_terrainGen0_167" type="box"/>
        </body>
        <body pos="0.000000 0.000000 187.125000" quat="1.000000 0.000000 0.000000 0.000000" name="tGen_terrainGen0_169">
            <geom conaffinity="1" contype="0" pos="0.000000 0.000000 0.000000" quat="1.000000 0.000000 0.000000 0.000000" size="0.250000 1.000000 0.012500" name="tGen_terrainGen0_169" type="box"/>
        </body>
        <body pos="0.000000 0.000000 188.149994" quat="1.000000 0.000000 0.000000 0.000000" name="tGen_terrainGen0_171">
            <geom conaffinity="1" contype="0" pos="0.000000 0.000000 0.000000" quat="1.000000 0.000000 0.000000 0.000000" size="0.250000 1.000000 0.012500" name="tGen_terrainGen0_171" type="box"/>
        </body>
        <body pos="0.000000 0.000000 189.174988" quat="1.000000 0.000000 0.000000 0.000000" name="tGen_terrainGen0_173">
            <geom conaffinity="1" contype="0" pos="0.000000 0.000000 0.000000" quat="1.000000 0.000000 0.000000 0.000000" size="0.250000 1.000000 0.012500" name="tGen_terrainGen0_173" type="box"/>
        </body>
        <body pos="0.000000 0.000000 190.199997" quat="1.000000 0.000000 0.000000 0.000000" name="tGen_terrainGen0_175">
            <geom conaffinity="1" contype="0" pos="0.000000 0.000000 0.000000" quat="1.000000 0.000000 0.000000 0.000000" size="0.250000 1.000000 0.012500" name="tGen_terrainGen0_175" type="box"/>
        </body>
        <body pos="0.000000 0.000000 191.225006" quat="1.000000 0.000000 0.000000 0.000000" name="tGen_terrainGen0_177">
            <geom conaffinity="1" contype="0" pos="0.000000 0.000000 0.000000" quat="1.000000 0.000000 0.000000 0.000000" size="0.250000 1.000000 0.012500" name="tGen_terrainGen0_177" type="box"/>
        </body>
        <body pos="0.000000 0.000000 192.250000" quat="1.000000 0.000000 0.000000 0.000000" name="tGen_terrainGen0_179">
            <geom conaffinity="1" contype="0" pos="0.000000 0.000000 0.000000" quat="1.000000 0.000000 0.000000 0.000000" size="0.250000 1.000000 0.012500" name="tGen_terrainGen0_179" type="box"/>
        </body>
        <body pos="0.000000 0.000000 193.274994" quat="1.000000 0.000000 0.000000 0.000000" name="tGen_terrainGen0_181">
            <geom conaffinity="1" contype="0" pos="0.000000 0.000000 0.000000" quat="1.000000 0.000000 0.000000 0.000000" size="0.250000 1.000000 0.012500" name="tGen_terrainGen0_181" type="box"/>
        </body>
        <body pos="0.000000 0.000000 194.299988" quat="1.000000 0.000000 0.000000 0.000000" name="tGen_terrainGen0_183">
            <geom conaffinity="1" contype="0" pos="0.000000 0.000000 0.000000" quat="1.000000 0.000000 0.000000 0.000000" size="0.250000 1.000000 0.012500" name="tGen_terrainGen0_183" type="box"/>
        </body>
        <body pos="0.000000 0.000000 195.324997" quat="1.000000 0.000000 0.000000 0.000000" name="tGen_terrainGen0_185">
            <geom conaffinity="1" contype="0" pos="0.000000 0.000000 0.000000" quat="1.000000 0.000000 0.000000 0.000000" size="0.250000 1.000000 0.012500" name="tGen_terrainGen0_185" type="box"/>
        </body>
        <body pos="0.000000 0.000000 196.350006" quat="1.000000 0.000000 0.000000 0.000000" name="tGen_terrainGen0_187">
            <geom conaffinity="1" contype="0" pos="0.000000 0.000000 0.000000" quat="1.000000 0.000000 0.000000 0.000000" size="0.250000 1.000000 0.012500" name="tGen_terrainGen0_187" type="box"/>
        </body>
        <body pos="0.000000 0.000000 197.375000" quat="1.000000 0.000000 0.000000 0.000000" name="tGen_terrainGen0_189">
            <geom conaffinity="1" contype="0" pos="0.000000 0.000000 0.000000" quat="1.000000 0.000000 0.000000 0.000000" size="0.250000 1.000000 0.012500" name="tGen_terrainGen0_189" type="box"/>
        </body>
        <body pos="0.000000 0.000000 198.399994" quat="1.000000 0.000000 0.000000 0.000000" name="tGen_terrainGen0_191">
            <geom conaffinity="1" contype="0" pos="0.000000 0.000000 0.000000" quat="1.000000 0.000000 0.000000 0.000000" size="0.250000 1.000000 0.012500" name="tGen_terrainGen0_191" type="box"/>
        </body>
        <body pos="0.000000 0.000000 199.424988" quat="1.000000 0.000000 0.000000 0.000000" name="tGen_terrainGen0_193">
            <geom conaffinity="1" contype="0" pos="0.000000 0.000000 0.000000" quat="1.000000 0.000000 0.000000 0.000000" size="0.250000 1.000000 0.012500" name="tGen_terrainGen0_193" type="box"/>
        </body>
        <body pos="0.000000 0.000000 200.449997" quat="1.000000 0.000000 0.000000 0.000000" name="tGen_terrainGen0_195">
            <geom conaffinity="1" contype="0" pos="0.000000 0.000000 0.000000" quat="1.000000 0.000000 0.000000 0.000000" size="0.250000 1.000000 0.012500" name="tGen_terrainGen0_195" type="box"/>
        </body>
        <body pos="0.000000 0.000000 201.475006" quat="1.000000 0.000000 0.000000 0.000000" name="tGen_terrainGen0_197">
            <geom conaffinity="1" contype="0" pos="0.000000 0.000000 0.000000" quat="1.000000 0.000000 0.000000 0.000000" size="0.250000 1.000000 0.012500" name="tGen_terrainGen0_197" type="box"/>
        </body>
    </worldbody>
</mujoco>
