<?xml version="1.0"?>
<robot name="walker">
  <link name="world"/>

  <link name="torso">
    <visual>
      <origin rpy="0 0 0" xyz="0 0 0"/>
      <geometry>
        <cylinder radius="0.07" length="0.6"/>
      </geometry>
    </visual>
    <collision>
      <origin rpy="0 0 0" xyz = "0 0 0"/>
      <geometry>
        <cylinder radius="0.07" length="0.6"/>
      </geometry>
    </collision>
    <inertial>
        <origin rpy="0 0 0" xyz="0 0 0"/>
        <mass value="1"/>
        <inertia ixx="0.002" ixy="0.0" ixz="0" iyy="0.002" iyz="0" izz="0.002"/>
    </inertial>
  </link>

  <link name="reference_1">
    <inertial>
        <origin rpy="0 0 0" xyz="0 0 0"/>
        <mass value="0"/>
        <inertia ixx="0" ixy="0" ixz="0" iyy="0" iyz="0" izz="0"/>
    </inertial>
  </link>

  <link name="reference_2">
    <inertial>
        <origin rpy="0 0 0" xyz="0 0 0"/>
        <mass value="0"/>
        <inertia ixx="0" ixy="0" ixz="0" iyy="0" iyz="0" izz="0"/>
    </inertial>
  </link>

  <link name="reference_3">
    <inertial>
        <origin rpy="0 0 0" xyz="0 0 0"/>
        <mass value="0"/>
        <inertia ixx="0" ixy="0" ixz="0" iyy="0" iyz="0" izz="0"/>
    </inertial>
  </link>

  <joint name="ref_plane_x" type="fixed">
    <parent link="world"/>
    <child link="reference_1"/>
    <origin xyz="0 0 0"/>
    <axis xyz="1 0 0"/>
  </joint>

  <joint name="ref_plane_z" type="prismatic">
    <parent link="reference_1"/>
    <child link="reference_2"/>
    <origin xyz="0 0 0"/>
    <axis xyz="1 0 0"/>
  </joint>

  <joint name="ref_rot_y" type="prismatic">
    <parent link="reference_2"/>
    <child link="reference_3"/>
    <origin xyz="0 0 0"/>
    <axis xyz="0 0 1"/>
  </joint>

  <joint name="plane_z" type="revolute">
    <parent link="reference_3"/>
    <child link="torso"/>
    <origin xyz="0 0 0"/>
    <axis xyz="0 1 0"/>
  </joint>

  <link name="right_thigh">
    <visual>
        <origin rpy="0 0 0" xyz="0 0 0"/>
        <geometry>
            <cylinder radius="0.05" length="0.45"/>
        </geometry>
    </visual>
    <collision>
        <origin rpy="0 0 0" xyz="0 0 0"/>
        <geometry>
            <cylinder radius="0.05" length="0.45"/>
        </geometry>
    </collision>
    <inertial>
        <origin rpy="0 0 0" xyz="0 0 0"/>
        <mass value="1"/>
        <inertia ixx="0.002" ixy="0.0" ixz="0" iyy="0.002" iyz="0" izz="0.002"/>
    </inertial>
  </link>

  <joint name="right_hip" type="revolute">
    <parent link="torso"/>
    <child link="right_thigh"/>
    <origin xyz="0.0 0.05 -0.3"/>
    <axis xyz="0 1 0"/>
  </joint>

  <link name="left_thigh">
    <visual>
        <origin rpy="0 0 0" xyz="0 0 0"/>
        <geometry>
            <cylinder radius="0.05" length="0.45"/>
        </geometry>
    </visual>
    <collision>
        <origin rpy="0 0 0" xyz="0 0 0"/>
        <geometry>
            <cylinder radius="0.05" length="0.45"/>
        </geometry>
    </collision>
    <inertial>
        <origin rpy="0 0 0" xyz="0 0 0"/>
        <mass value="1"/>
        <inertia ixx="0.002" ixy="0.0" ixz="0" iyy="0.002" iyz="0" izz="0.002"/>
    </inertial>
  </link>

  <joint name="left_hip" type="revolute">
    <parent link="torso"/>
    <child link="left_thigh"/>
    <origin xyz="0.0 -0.05 -0.3"/>
    <axis xyz="0 1 0"/>
  </joint>

</robot>


