<mujoco model="pendulum">

  <worldbody>
    <body name="pole" pos="0 0 .6">
      <joint name="hinge" type="hinge" axis="0 1 0" damping="0.1"/>
      <geom name="base" material="decoration" type="cylinder" fromto="0 -.03 0 0 .03 0" size="0.021" mass="0"/>
      <geom name="pole" material="self" type="capsule" fromto="0 0 0 0 0 0.5" size="0.02" mass="0"/>
      <geom name="mass" material="effector" type="sphere" pos="0 0 0.5" size="0.05" mass="1"/>
    </body>
  </worldbody>

  <actuator>
    <motor name="torque" joint="hinge" gear="1" ctrlrange="-1 1" ctrllimited="true"/>
  </actuator>
</mujoco>